Workbook

Sheet Original
A1: No Urut | B1: Nama MKS | C1: No Rekening Pinjaman | D1: No Rekening Tabungan | E1: Nama Nasabah | F1: Baki Debet | G1: Baki Debet | I1: Blokir | J1: Nominal | K1: Tabungan | L1: Angsuran | M1: Kol | N1: Hari Tunggakan | O1: Nama Perusahaan | P1: Alamat | Q1: No. Telepon | R1: Nama Perusahaan | S1: Limit | T1: Baki Debet | U1: Tunggakan Pokok | V1: Tunggakan Bunga | W1: Denda | X1: Total Tunggakan | Y1: Total Kewajiban | Z1: Kol | AA1: Hari Tunggakan | AB1: Loan Acct Status | AC1: Jatuh Tempo Pinjaman | AD1: Jatuh Tempo Tagihan | AE1: Last Payment Date | AF1: Installment amount | AG1: AGF Account 1 | AH1: AGF Account 1 Balance | AI1: AGF Account 2 | AJ1: AGF Account 2 Balance | AK1: BDM Color | AL1: Product | AM1: AGF Account 1 | AN1: AGF Account 1 Balance | AO1: AGF Account 2 | AP1: AGF Account 2 Balance | AQ1: BDM Color | AR1: Product
A2: 1 | C2: 1100102173264 | D2: 1100012703994 | E2: GIANTI | J2: 165000
A3: 2 | C3: 1100102671721 | D3: 1100019193207 | E3: ABDULLAH BAHRI | J3: 126000 | R3: Desa Tugu Mulyo DS III RT 003 Lempuing 000030657 | S3: /085384662555 | T3: KUR Penjaminan PERUM JAMKRINDO (Perhitungan Credit Line Penjaminan Kredit) | U3: 100000000
A4: 3 | C4: 1100102896500 | D4: 1100021522898 | E4: ARTIFAN | J4: 157000 | R4: Desa Kerta Mukti RT 006 RW 003 Mesuji Raya 000030681 | S4: /082337983488 | T4: JUAL BELI SAPI | U4: 100000000
A5: 4 | C5: 1100102897359 | D5: 1100021547606 | E5: ROHID HIDAYAT | J5: 75000 | R5: Dusun III Embacang RT 003 RW 002 Mesuji Raya 000030657 | S5: /085282833993 | T5: KUR Penjaminan PERUM JAMKRINDO (Perhitungan Credit Line Penjaminan Kredit) | U5: 20000000
A6: 5 | C6: 1100102707756 | D6: 1100019507687 | E6: PUPUT WARYANTO | J6: 142000 | O6: PELUNASAN | R6: Dusun II Desa DAbuk Makmur RT 003 RW 003 Mesuji Raya 000030681 | S6: tidak memiliki | T6: WARUNG MANISAN DAN SEMBAKO | U6: 100000000
A7: 6 | C7: 1100102896641 | D7: 1100021489338 | E7: DESMALA | J7: 74000 | R7: Dusun II Desa Kerta Mukti RT 001 RW 002 Mesuji Raya 000030681 | S7: tidak memiliki | T7: KUR Penjaminan PERUM JAMKRINDO (Perhitungan Credit Line Penjaminan Kredit) | U7: 70000000
A8: 7 | C8: 1100102924815 | D8: 1100014601949 | E8: RHOHINO | J8: 21000
A9: 8 | C9: 1100102744940 | D9: 1100019864575 | E9: RULLY NOVIANA | J9: 27000
A10: 9 | C10: 1100102969323 | D10: 1100022370719 | E10: WAHYU RAHMADANI | J10: 23000
A11: 10 | C11: 1100102969364 | D11: 1100022521196 | E11: IKA EVI YANI | J11: 23000
A12: 11
A13: 12
A14: 13
A15: 14 | B15: aaaa
A16: 15
A17: 16
A18: 17
A19: 18
A20: 19
A21: 20 | K21: BLM POSTING
A22: 21 | K22: MTR
A23: 22 | B23: v | K23: BLM POSTING
A24: 23 | B24: v
A25: 24 | K25: MTR
A26: 25
A27: 26
A28: 27
A29: 28
A30: 29
A31: 30
A32: 31
A33: 32
A34: 33
A35: 34
A36: 35
A37: 36
... A49: 48
A50: 49 | Q50: TIDAK ADA | R50: KUR Penjaminan PERUM JAMKRINDO (Perhitungan Credit Line Penjaminan Kredit) | S50: 25000000 | T50: 8202728.6 | U50: 917496.22 | V50: 0 | W50: 0 | X50: 917496.22 | Y50: 8202728.6 | Z50: 2A | AA50: 3 | AB50: 1 | AC50: 43277 | AD50: 43065 | AE50: 43065 | AF50: 1141667 | AG50: 1120011706640 | AH50: 50001 | AJ50: 0 | AK50: GREEN
A51: 50 | Q51: tidak ada | R51: KUR Penjaminan PERUM JAMKRINDO (Perhitungan Credit Line Penjaminan Kredit) | S51: 30000000 | T51: 21220194 | U51: 1250000 | V51: 93707.26 | W51: 0 | X51: 1343707.3 | Y51: 21313901 | Z51: 2A | AA51: 13 | AB51: 1 | AC51: 43540 | AD51: 43055 | AE51: 43055 | AF51: 1370000 | AG51: 1120012053315 | AH51: 1500000 | AJ51: 0 | AK51: GREEN
...

Sheet Advis
A1: 10 | B1: <<------ masukkan nomor yang akan dicetak advis nya
D2: =VLOOKUP(A1,Sheet1!B4:t88,1)
C5: Nama | D5: : | E5: =VLOOKUP(A1,Original!A1:AL101,5) -> IKA EVI YANI | H5: NO GNC | J5: : | K5: 1 | O5: 113-0009891445
C6: Alamat | D6: : | E6: =VLOOKUP(A1,Original!A1:AL101,16) -> 0 | H6: NAMA GNC | J6: : | K6: GNC PNPL 11288 | O6: GNC Mikro
C7: No Rekening Tabungan | D7: : | E7: =VLOOKUP(A1,Original!A1:AL101,4) -> 1100022521196 | H7: NAMA TTD | J7: : | K7: -
C8: No Rekening Pinjaman | D8: : | E8: =VLOOKUP(A1,Original!A1:AL101,3) -> 1100102969364
C9: Jumlah | D9: : | E9: =VLOOKUP(A1,Original!A1:AL101,10) -> 23000 | O9: 4056-Angsuran
C10: Pesan | D10: : | E10: Pembayaran Angsuran | O10: 4052-Angsuran dari GNC
C11: Kotran | D11: : | E11: 4056-Angsuran | O11: 4204-Pelunasan
O12: 1314-GNC ke Tabungan
O13: 4234-Penarikan Kelebihan Bayar
C14: =NOW() -> 46314.614 | O14: 4104 - Pelunasan Pokok Sebagian
E16: ="Yth. "&E5 -> Yth. IKA EVI YANI
E17: =IF(E11="4056-angsuran",(E8),IF(E11="4052-Angsuran dari GNC",(E8),IF(E11="4204-Pelunasan",(E8),IF(E11="1314-GNC ke Tabungan",(E7),IF(E11="4234-Penarikan Kelebihan Bayar",(E7),IF(E11="4104 - Pelunasan Pokok Sebagian",(E8))))))) -> 1100102969364
E18: =E6 -> 0
C19: =IF(E11="4056-angsuran","Kotran 4056",IF(E11="4052-Angsuran dari GNC","Kotran 4052",IF(E11="4204-Pelunasan","Kotran 4204",IF(E11="1314-GNC ke Tabungan","Kotran 1314",IF(E11="4234-Penarikan Kelebihan Bayar","Kotran 4234",IF(E11="4104 - Pelunasan Pokok Sebagian","Kotran 4104")))))) -> Kotran 4056 | D19: =E9 -> 23000
C20: =IF(E11="4056-angsuran","Pembayaran Angsuran",IF(E11="4052-Angsuran dari GNC","Pembayaran Angsuran",IF(E11="4204-Pelunasan","Pelunasan Kredit",IF(E11="1314-GNC ke Tabungan","Pindah Buku",IF(E11="4234-Penarikan Kelebihan Bayar","Penarikan Kelebihan Bayar",IF(E11="4104 - Pelunasan Pokok Sebagian","Pelunasan Pokok Sebagian")))))) -> Pembayaran Angsuran
B23: =IF(E11="4056-angsuran"," ",IF(E11="4052-Angsuran dari GNC","Reff",IF(E11="4204-Pelunasan"," ",IF(E11="1314-GNC ke Tabungan","Reff",IF(E11="4234-Penarikan Kelebihan Bayar"," ",IF(E11="4104 - Pelunasan Pokok Sebagian"," ")))))) | F23: =IF(D25<0,"&sen","")
D25: =D19 -> 23000
C26: ='Rumus '!A48 -> #N/A
C30: D/ | D30: =IF(E11="4056-angsuran",(E7),IF(E11="4052-Angsuran dari GNC",K5,IF(E11="4204-Pelunasan",(E7),IF(E11="1314-GNC ke Tabungan",(K5),IF(E11="4234-Penarikan Kelebihan Bayar",(E8),IF(E11="4104 - Pelunasan Pokok Sebagian",(E7))))))) -> 1100022521196
D31: =IF(E11="4056-angsuran",(E5),IF(E11="4052-Angsuran dari GNC",K6,IF(E11="4204-Pelunasan",E5,IF(E11="1314-GNC ke Tabungan",(K6),IF(E11="4234-Penarikan Kelebihan Bayar",(E5),IF(E11="4104 - Pelunasan Pokok Sebagian",(E5))))))) -> IKA EVI YANI | F31: =K7 -> -

Sheet All Suspend
C2: No GNC | D2: : | E2: 112-00-0706273-5 | H2: 1209 - Debet Giro ke GL | I2: 195 116 01
C3: Nama GNC | D3: : | E3: GNC - PNPL Asuran (11277) | H3: 1208 - Debet GL ke Giro | I3: 210 112 06 | K3: 112-00-1105617-8
C4: No GNC Tujuan | D4: : | E4: 112-00-1202930-7 | H4: 1314 - Debet Giro ke Tabungan | I4: 195 116 20 | K4: GNC Cluster Tugumulyo
C5: Nama GNC Tujuan | D5: : | E5: Ahmad Munharib | H5: 1107 - Kredit Giro Debit GL | K5: 112-00-1032445-2
C6: Nominal | D6: : | E6: 400000 | H6: 1417 - Pembulatan | K6: Ari Gusman
C7: Noted | D7: : | E7: JRB.R01.BR/MTU/106/2022 | H7: 7016 - Pembayaran tagihan dari Giro | K7: 112-00-1491876-2
C8: Refferensi | D8: : | E8: 0000 0000 2022 1575 430 | K8: 19511601
C9: Jenis Suspend | D9: : | E9: 195 116 01 | F9: =IF(E9="195 116 01","All Suspen Deposit",IF(E9="210 112 06","Pajak YMHD PPH Final Bunga Simpanan",IF(E9="195 116 20","All Rek Suspend Apl",0))) -> All Suspen Deposit | J9: 0.87
C10: Kotran | D10: : | E10: 1314 - Debet Giro ke Tabungan
C13: 11277 - KCP MMU Martapura | F13: =NOW() -> 46314.614
F15: =IF(E10="1209 - Debet Giro ke GL","K/ "&(E9),IF(E10="1208 - Debet GL ke Giro","D/ "&(E9),IF(E10="1314 - Debet Giro ke Tabungan","D/ "&(E2),IF(E10="1107 - Kredit Giro Debit Gl","D/ "&(E9),IF(E10="1417 - Pembulatan",(E2),IF(E10="7016 - Pembayaran Tagihan dari Giro","D/ "&(E2))))))) -> D/ 112-00-0706273-5 | I15: 1120007062735
E16: =IF(E10="1209 - Debet Giro ke GL",(F9),IF(E10="1208 - Debet GL ke Giro",(F9),IF(E10="1314 - Debet Giro ke Tabungan",(E3),IF(E10="1107 - Kredit Giro Debit GL",(F9),IF(E10="1417 - Pembulatan",(E3),IF(E10="7016 - Pembayaran Tagihan dari Giro",(E3))))))) -> GNC - PNPL Asuran (11277)
E17: =E3 -> GNC - PNPL Asuran (11277)
B18: =IF(E10="1209 - Debet Giro ke GL","Kotran 1209",IF(E10="1208 - Debet GL ke Giro","Kotran 1208",IF(E10="1314 - Debet Giro ke Tabungan","Kotran 1314",IF(E10="1301 - Penariakan Tunai Giro","Kotran 1301",IF(E10="1107 - Kredit Giro Debit GL","Kotran 1107",IF(E10="1417 - Pembulatan","Kotran 1417",IF(E10="7016 - Pembayaran Tagihan dari Giro","Kotran 7016"))))))) -> Kotran 1314 | D18: =E6 -> 400000
B19: =E7 -> JRB.R01.BR/MTU/106/2022
B22: =IF(E10="1209 - Debet Giro ke GL","Reff "&(E8),IF(E10="1208 - Debet GL ke Giro"," ",IF(E10="1314 - Debet Giro ke Tabungan","Reff "&(E8),IF(E10="1107 - Kredit Giro Debit GL"," ",IF(E10="1417 - Pembulatan","Reff "&(E8),IF(E10="7016 - Pembayaran Tagihan dari Giro",(E8))))))) -> Reff 0000 0000 2022 1575 430 | F22: =IF(D24<0,"&sen","")
D24: =E6 -> 400000
C25: ='Rumus '!A295 -> #N/A
B28: =IF(E10="1209 - Debet Giro ke GL","D/ "&(E2),IF(E10="1208 - Debet GL ke Giro","K/ "&(E4),IF(E10="1314 - Debet Giro ke Tabungan","K/ "&(E4),IF(E10="1107 - Kredit Giro Debit Gl","K/ "&(E2),IF(E10="1417 - Pembulatan","K/ 036 Fee Lainnya",IF(E10="7016 - Pembayaran Tagihan dari Giro","K/ "&(E4))))))) -> K/ 112-00-1202930-7
B29: =IF(E10="1209 - Debet Giro ke GL",(E3),IF(E10="1208 - Debet GL ke Giro",(E5),IF(E10="1314 - Debet Giro ke Tabungan",(E5),IF(E10="1107 - Kredit Giro Debit Gl",(E3),IF(E10="1417 - Pembulatan"," ",IF(E10="7016 - Pembayaran Tagihan dari Giro",(E5))))))) -> Ahmad Munharib
F30: (Fredi Yulianto/F.595)
C38: 3219434 | E38: 025 OPERASIONAL
C39: 1263110 | E39: 026 LISTRIK
C40: 250000
C41: 1000000 | E41: 295RETRIBUSI JASA KEBERSIHAN JANUARI2022

Sheet Debet Suspend
M1: Kotran 0001 | O1: All Suspend Deposit - 195 116 01
B2: All Akun Susp Transaksi Antar APL - 195 116 20 | M2: Kotran 0002 | O2: All Akun Susp Transaksi Antar APL - 195 116 20
C4: KCP MMU MARTAPURA
B5: Kotran 0002
C6: =IF(B5="Kotran 0002","KCP MMU Martapura",IF(B5="Kotran 0001","All Suspend Deposit - 195 116 01")) -> KCP MMU Martapura
C7: M2M PUSLATPUR | G7: 3950000
B8: =IF(B5="Kotran 0002","D/ "&B2,IF(B5="Kotran 0001","D/ Tunai")) -> D/ All Akun Susp Transaksi Antar APL - 195 116 20 | K8: 126000
B9: =IF(B5="Kotran 0002","K/ Tunai",IF(B5="Kotran 0001","K/ "&B2,0)) -> K/ Tunai | K9: 48000
G12: =G7 -> 3950000
B14: ='Rumus '!A416 -> #N/A
F16: Martapura, | G16: =NOW() -> 46314.614
F19: Fredi Yulianto
F20: F.595
B23: 118 LISTRIK
B24: 117 OPERASIONAL
B25: MANY TO MANY PUSLATPUR
B26: POT PUSLATPUR
B27: Premi Asmik
B28: PPH Pasal 4 Bunga Simpanan
B29: pengembalian biaya provisi dan add]00002
B30: 085 Operasional
B31: M2M PUSLATPUR
B32: 143 OPERASIONAL
B33: 144 PLN
B34: 048 Listrik

Sheet Nota Pulsa & Listrik
L4: Pulsa
A6: Nomor | C6: : | D6: JRB.R02.MTU/145B/2022 | I6: Business Area | J6: : BC77
A7: Tanggal | C7: : | D7: 44714 | I7: URC | J7: : 11277M
A8: Perihal | C8: : | D8: =IF(L4="Listrik",(C50),IF(L4="Pulsa",(C51),IF(L4="Listrik Kantor",(C52)))) -> Permohonan Reimburse Tunjangan Pulsa | I8: Fund Center | J8: : -
A9: Dari | C9: : | D9: KCP MMU Palembang Martapura | I9: Internal Order | J9: : 11277M01
A10: Kepada | C10: : | D10: Business Support Area Palembang Sudirman
A12: A. | B12: DEBET
A13: No. | B13: Nomor & Nama Akun Buku Besar | C13: Nama Pegawai | F13: Nota Ke | G13: Tanggal Nota | H13: Keterangan | J13: Nominal
C14: Nama | E14: NIP
A15: 1 | B15: =IF(L4="Listrik",(B50),IF(L4="Pulsa",(B51),IF(L4="Listrik Kantor",(B52)))) -> 540.112.06 BTK Beban Tunjangan Pulsa Telepon Genggam | C15: Fredi Yulianto | E15: 1285460275 | F15: 1 | G15: 44691 | H15: =IF(L4="Listrik",(E50),IF(L4="Pulsa",(E51),IF(L4="Listrik Kantor",(E52)))) -> Biaya Tunjangan Pulsa Branch Manager Bulan Mei 2022 | J15: 200000
A17: GRAND TOTAL | J17: =J15 -> 200000
A19: B. | B19: KREDIT
A20: Nama Pemilik Rekening / Nama | C20: : | D20: Fredi Yulianto
A21: No. Rekening | C21: : | D21: 112-00-5111111-5
A24: PT. Bank Mandiri (Persero) Tbk,
A25: KCP MMU Martapura
A30: Fredi Yulianto
A31: Branch Manager
B44: Listrik
B45: Pulsa
B50: 540.112.19 BTK TUNJANGAN UTILITIS | C50: Permohonan Reimburse Tunjangan Utilitis | E50: Biaya Tunjangan Utilitis Branch Manager Bulan Mei 2022
B51: 540.112.06 BTK Beban Tunjangan Pulsa Telepon Genggam | C51: Permohonan Reimburse Tunjangan Pulsa | E51: Biaya Tunjangan Pulsa Branch Manager Bulan Mei 2022
B54: Biaya Utilities Listrik Branch Manager Bulan Desember 2021
B55: Biaya Tunjangan Pulsa Branch Manager Bulan Desember 2021
H60: 530.112.01 | I60: BEBAN LISTRIK, AIR & GAS KANTOR

Sheet Nota Jasa Kebersihan
B5: Nomor | C5: : | F5: JRB.R02.MTU/146/2022 | H5: Business Area | I5: : BC77
B6: Tanggal | C6: : | F6: 02 Juni 2022 | H6: URC | I6: : 11277M | L6: 1272920
B7: Perihal | C7: : | F7: Permohonan Reimburse Jasa Kebersihan Kantor | H7: Fund Center | I7: : - | L7: 1276420
B8: Dari | C8: : | F8: KCP MMU Palembang Martapura | H8: Internal Order | I8: : 11277M01 | L8: =L7-L6 -> 3500
B9: Kepada | C9: : | F9: Business Support Area Palembang Sudirman
A11: A. | B11: DEBET
A12: No. | B12: Nomor & Nama Akun Buku Besar | C12: No Nota | F12: Tanggal Nota | G12: Keterangan | I12: Nominal
A14: 1 | B14: 530.112.07 BEBAN BARANG PIHAK KETIGA | C14: 1 | F14: 44706 | G14: Biaya Jasa Kebersihan Kantor Bulan Mei 2022 | I14: 850000
A18: GRAND TOTAL | I18: =I14+I15 -> 850000
A20: B. | B20: KREDIT
A21: Nama GNC | C21: : | F21: PNPL CASH ASURAN
A22: No. Rekening / GNC | C22: : | F22: 112-00-0706273-5
A25: PT. Bank Mandiri (Persero) Tbk,
A26: KCP MMU Martapura
A31: Fredi Yulianto
A32: Branch Manager

Sheet Nota Listrik Kantor
B5: Nomor | C5: : | F5: JRB.R02.MTU/144/2022 | H5: Business Area | I5: : BC77
B6: Tanggal | C6: : | F6: 02 Juni 2022 | H6: URC | I6: : 11277M
B7: Perihal | C7: : | F7: Permohonan Reimburse Listrik Kantor | H7: Fund Center | I7: : -
B8: Dari | C8: : | F8: KCP MMU Palembang Martapura | H8: Internal Order | I8: : 11277M01
B9: Kepada | C9: : | F9: Business Support Area Palembang Sudirman
A11: A. | B11: DEBET
A12: No. | B12: Nomor & Nama Akun Buku Besar | C12: No Nota | F12: Tanggal Nota | G12: Keterangan | I12: Nominal
A14: 1 | B14: 530.112.01-01 Beban Listrik Kantor | C14: 1 | F14: 44714 | G14: Biaya Listrik Kantor Bulan Juni 2022 | I14: 915840
A18: GRAND TOTAL | I18: =I14 -> 915840
A20: B. | B20: KREDIT
A21: Nama GNC | C21: : | F21: PNPL CASH ASURAN
A22: No. Rekening / GNC | C22: : | F22: 112-00-0706273-5
A25: PT. Bank Mandiri (Persero) Tbk,
A26: KCP MMU Martapura
A31: Fredi Yulianto
A32: Branch Manager

Sheet Nota
A5: Nomor | C5: : JRB.R02.MTU/143/2022 | H5: Business Area | I5: : BC77
A6: Tanggal | C6: : 02 Juni 2022 | H6: URC | I6: : 11277M
A7: Perihal | C7: : Permohonan Reimburse Operasional | H7: Fund Center | I7: : -
A8: Dari | C8: : KCP MMU Palembang Martapura | H8: Internal Order | I8: : 11277M01
A9: Kepada | C9: : Business Support Area Palembang Sudirman
A11: A. | B11: DEBET
A12: No. | B12: Nomor & Nama Akun Buku Besar | C12: No Nota | F12: Tanggal Nota | G12: Keterangan | I12: Nominal
A13: 1 | B13: 530.112.07 | C13: 1 | F13: 44692 | G13: Bingkai Penghargaan | I13: 40000
B14: Beban Barang | C14: 2 | F14: 44697 | G14: Spanduk HUT Prov Sumsel | I14: 96000
B15: Pihak Ketiga | C15: 3 | F15: 44698 | G15: Door Sensor | I15: 78300
C16: 4 | F16: 44699 | G16: Akrilik Display Qris 7 Buah | I16: 70000
C17: 5 | F17: 44699 | G17: Karet Gelang Merah | I17: 10000
C18: 6 | F18: 44702 | G18: Makan Weekend Bangking 21/05/2022 | I18: 150000
C19: 7 | F19: 44704 | G19: Isi Ulang 2 Air Galon | I19: 14000
C20: 8 | F20: 44709 | G20: Makan Weekend Bangking 28/05/2022 | I20: 150000
C21: 9 | F21: 44710 | G21: Jasa Las Kursi CSR | I21: 50000
C22: 10 | F22: 44711 | G22: Karet Warna Hijau | I22: 55000
C23: 11 | F23: 44712 | G23: Makan Lembur Tgl 31/05/2022 | I23: 180000
A36: TOTAL | I36: =SUM(I13:I35) -> 893300
A38: 2 | B38: 530.112.08 | C38: 12 | F38: 44691 | G38: Kwitansi dan Lem | I38: 22500
B39: Beban Alat Tulis | C39: 13 | F39: 44698 | G39: Tinta Eoson 774 BK | I39: 190000
B40: Kantor | C40: 14 | F40: 44700 | G40: Kertas A4 1 dua | I40: 205000
C41: 15 | F41: 44702 | G41: Cartridge Epson LQ 2180/2190 | I41: 123000
C42: 16 | F42: 44702 | G42: Cartridge Epson PLQ20 | I42: 165000
C48: 17 | F48: 44711 | G48: Kertas Stiker Untuk Cetak Qris | I48: 40720
A50: TOTAL | I50: =SUM(I38:I49) -> 746220
A52: 3 | B52: 530.113.01 | C52: 18 | F52: 44704 | G52: Retribusi Kebersihan Bulan Mei | I52: 35000
B53: Beban Pemeliharaan
B54: Halaman
B55: /Gedung Kantor
A56: TOTAL | I56: =SUM(I52:I55) -> 35000
A58: 4 | B58: 530.113.01 | C58: 19 | F58: 44691 | G58: Pengiriman Reimbes via J&T | I58: 15000
B59: Beban Ekspedisi | C59: 20 | F59: 44692 | G59: Jasa Kirim Mesin EDC Agen upgrade | I59: 100000
C60: 21 | F60: 44711 | G60: Pengiriman Mesin Agen ke Area via J&T | I60: 75000
A62: TOTAL | I62: =SUM(I58:I61) -> 190000
A64: 5 | B64: 530.113.04 | C64: 22 | F64: 44699 | G64: Dexlite Genset | I64: 100000
B65: Beban Pemeliharaan
B66: Inventaris Kantor
A70: TOTAL | I70: =SUM(I64:I69) -> 100000
A72: 6 | B72: 530.112.01-02 | C72: 23 | F72: 44706 | G72: PDAM | I72: 113000
...

Sheet Sheet3
B3: REVISI NOTA dan ADVIS
B4: - Surat No JRB.R02.MTU/117/2022 Tanggal 10 Mei 2022 - Buku Besar 530.112.01-02
B5: - Surat No JRB.R02.MTU/118/2022 Tanggal 10 Mei 2022 - Buku Besar 530.112.01-01
B8: REVISI NOTA dan ADVIS
B9: - Surat No JRB.R02.MTU/143/2022 Tanggal 02 Juni 2022 - Buku Besar 530.112.01-02
B10: - Surat No JRB.R02.MTU/144/2022 Tanggal 02 Juni 2022 - Buku Besar 530.112.01-01

Sheet Data Buku Besar
A1: No | B1: Nomor Buku Besar | C1: Nama Buku Besar | D1: Nominal | E1: Penggunaan | F1: Contoh Penggunaan
A2: 1 | B2: 530.111.01 | C2: BEBAN TELPON DAN FAX | D2: =Nota!I80 -> 385450 | E2: Indihome Bulan Juni 2022 No 1117671023399 | F2: Bayar tagihan telpon & fax kantor
A3: 2 | B3: 530.112.01-01 | C3: BEBAN LISTRIK KANTOR | D3: ='Nota Listrik Kantor'!I18 -> 915840 | E3: Tagihan Listrik/PLN Juni 2022 | F3: Bayar tagihan PLN, PDAM kantor, solar genset
A4: 2A | B4: 530.112.01-02 | C4: BEBAN AIR KANTOR | D4: =Nota!I75 -> 113000 | E4: PDAM
A5: 2B | B5: 530.112.01-03 | C5: BEBAN GAS KANTOR
A6: 3 | B6: 530.112.02 | C6: BEBAN LISTRIK, AIR & GAS RUMAH DINAS | F6: Bayar tagihan PLN, PDAM rumah dinas yang menjadi asset Bank Mandiri
A7: 4 | B7: 530.112.03 | C7: BEBAN PERLENGKAPAN KANTOR | F7: Pembelian u/ penggantian kursi, meja, filling kabinet yg sudah rusak
A8: 5 | B8: 530.112.06 | C8: BEBAN MATERAI | F8: Pembelian materai
A9: 6 | B9: 530.112.07 | C9: BEBAN BARANG PIHAK KETIGA | D9: =Nota!I36 -> 893300 | E9: Bingkai, Spanduk, Door Sensor, Akrilik, Karet, Makan Lembur, Isi Ulang Air Galon, dan Jasa Las | F9: Pemenuhan kebutuhan logistik pantry/konsumsi rapat, pembayaran speedy/TV kabel papan kurs atau ruang prioritas
A10: 6A | B10: 530.112.07 | C10: BEBAN BARANG PIHAK KETIGA | D10: 850000 | E10: Biaya Jasa Kebersihan Kantor Bulan Mei 2022 | F10: Pemenuhan kebutuhan logistik pantry/konsumsi rapat, pembayaran speedy/TV kabel papan kurs atau ruang prioritas
A11: 7 | B11: 530.112.08 | C11: BEBAN ALAT TULIS KANTOR | D11: =Nota!I50 -> 746220 | E11: Kwitansi, Lem, Kertas, Cartridge dan Kertas Stiker | F11: Pembelian alat tulis kantor
A12: 8 | B12: 530.112.10 | C12: BEBAN JASA PIHAK KETIGA | F12: Pembayaran jasa kebersihan kantor
A13: 9 | B13: 530.112.11 | C13: BEBAN KRIYA MANDIRI | F13: Perdin Kriya
A14: 10 | B14: 530.113.01 | C14: BEBAN PEMELIHARAAN BGNAN/HLM KTR | D14: 35000 | E14: Biaya Retribusi Sampah Mei 2022 | F14: Perbaikan bagian bangunan/halaman kantor yang rusak, pembayaran jasa cleaning service
A15: 11 | B15: 530.113.02 | C15: BEBAN PEMELIHARAAN BGNAN/HLM RUMDIN | F15: Perbaikan bagian bangunan/halaman rumah dinas yang rusak
A16: 12 | B16: 530.113.04 | C16: BEBAN PEMELIHARAAN INVENTARIS KANTOR | D16: =Nota!I70 -> 100000 | E16: Solar Genset | F16: Servis AC/printer
A17: 13 | B17: 530.113.05 | C17: BEBAN PEMELIHARAAN KENDARAAN BERMOTOR | F17: Servis/perlengkapan kebersihan/perlengkapan alat bengkel kendaraan/biaya parkir
A18: 14 | B18: 530.113.06 | C18: BEBAN PEMELIHARAAN MESIN KANTOR/PERCETAKAN | F18: Servis Mesin Hitung Uang, pembayaran media cetak berlangganan
A19: 15 | B19: 530.115.01 | C19: BEBAN SEWA RUMAH DINAS | F19: Pembayaran sewa rumah dinas/kost officer
A20: 16 | B20: 530.115.02 | C20: BEBAN SEWA KEPERLUAN KANTOR LAINNYA | F20: Sewa mesin fotocopy
A21: 17 | B21: 530.115.03 | C21: BEBAN SEWA RUANG KANTOR | E21: Biaya tagihan perpanjangan Sewa Gedung Kantor KCP MMU Martapura | F21: Sewa gedung kantor
A22: 18 | B22: 530.115.04 | C22: BEBAN SEWA KENDARAAN | F22: Sewa kendaraan dinas
A23: 19 | B23: 530.116.01 | C23: BEBAN HUMAS PENGEMBANGAN USAHA | F23: Pembayaran Bunga Papan, Sponsorship
A24: 20 | B24: 530.121.01 | C24: BEBAN PREMI ASURANSI NON KREDIT | F24: Pembayaran staco/CIT ATM/titipan kas BI
A25: 21 | B25: 530.131.01 | C25: BEBAN KEAMANAN | F25: Biaya jasa pengawalan remise/cash supply, perlengkapan keamanan/atk security
A26: 22 | B26: 530.131.02 | C26: BEBAN PENGANGKUTAN | D26: =Nota!I87 -> 200000 | E26: Pertamax BM | F26: BBM kendaraan dinas kantor
A27: 23 | B27: 530.131.10 | C27: BEBAN EXPEDISI | D27: =Nota!I62 -> 190000 | E27: Pengiriman via J&T | F27: Biaya pengiriman paket/dokumen
A28: 24 | B28: 530.131.13 | C28: BEBAN PERJALANAN DINAS DN | D28: 400000 | E28: Biaya Perdin Refresment KSM dan Rewarding Program Numpang Tenar | F28: Biaya perdin pegawai PKWT/Tetap
A29: 25 | B29: 540.112.06 | C29: BTK TUNJANGAN PULSA TELEPON GENGGAM | D29: 200000 | E29: Tunjangan Pulsa Branch Manager Bulan Mei 2022 | F29: Untuk Officer yang mendapat fasilitas tunjangan telepon genggam
A30: 26 | B30: 540.112.19 | C30: BTK TUNJANGAN UTILITIS | D30: 500000 | E30: Biaya Utilities Listrik Bulan Mei 2022 Branch Manager | F30: Untuk level Area Head & Kepala Cabang
A31: 27 | B31: 540.115.2314 | C31: BTK JASA TENAGA KERJA PIHAK KETIGA | F31: Pembayaran perdin pegawai TAD (driver, pramubhakti, security)

Sheet Buku Besar
B1: 2A | C1: <<------ masukkan no urut buku besar
C2: Nomor Buku Besar | D2: : | E2: =VLOOKUP(B1,'Data Buku Besar'!A1:F31,2) -> #N/A | J2: 1209 - Debet Giro ke GL | K2: 195 116 01
C3: Nama Buku Besar | D3: : | E3: =VLOOKUP(B1,'Data Buku Besar'!A1:F31,3) -> #N/A | J3: 1208 - Debet GL ke Giro | K3: 210 112 06 | M3: 112-00-1105617-8
C4: Nominal | D4: : | E4: =VLOOKUP(B1,'Data Buku Besar'!A1:F31,4) -> #N/A | J4: 1314 - Debet Giro ke Tabungan | K4: 195 116 20 | M4: GNC Cluster Tugumulyo
C5: Penggunaan | D5: : | E5: =VLOOKUP(B1,'Data Buku Besar'!A1:F31,5) -> #N/A | J5: 1107 - Kredit Giro Debit GL | M5: 112-00-1032445-2
C8: 11277 - KCP MMU Martapura | G8: =NOW() -> 46314.614
H10: =E2 -> #N/A
E11: =E3&" - 11277 " -> #N/A
E12: =E3 -> #N/A
B14: Pembebanan Biaya/KCP MMU Martapura (11277M01) | H14: =E4 -> #N/A
B15: =E5 -> #N/A
H18: =IF(D22<0,"&sen","")
H21: =H14 -> #N/A
B22: ='Rumus '!A537 -> #N/A
C25: 112-00-0706273-5
C27: GNC PNPL Ansuran 11277
G28: (Fredi Yulianto/F.595)

Sheet Kop Judul
A2: 530.112.07 - BEBAN BARANG PIHAK KETIGA
A4: 530.112.08 - BEBAN ALAT TULIS KANTOR
A6: 530.113.01 - BEBAN PEMELIHARAAN BANGUNAN/HALAMAN KANTOR
A8: 530.113.04 - BEBAN PEMELIHARAAN INVENTARIS KANTOR
A10: 530.131.10 - BEBAN EXPEDISI
A12: 530.112.01 - BEBAN LISTRIK KANTOR
A14: 530.112.02 - BEBAN AIR KANTOR
A16: 530.111.01 - BEBAN TELPON DAN FAX
A18: 530.131.02 - BEBAN PENGANGKUTAN

Sheet OVB All Suspend
O1: 1314-GNC ke Tabungan
C3: Martapura, | D3: =NOW() -> 46314.614
C5: OVB | E5: All Suspend Deposit
E6: K/ 195.116.01
E7: =#REF! -> #REF!
C8: Pemindahanbukuan Dari Rekening | D8: 811000
C9: D/ 112-00-0706273-5 (GNC 11277)
C11: Tarik tunai Petty Cash + Tunj Pulsa
C14: Ref : 0000-0000-2016-2875-430 | D14: =D8 -> 811000
C15: ='Rumus '!A172 -> #N/A
D19: D/ 112-00-0706273-5
D20: GNC - PNPL Asuran (11277) | F20: Fredi Yulianto
B27: Palembang Sako Kenten
C37: =fredi(D36)&" rupiah" -> #VALUE!
D41: 113-0009891445
D42: GNC | F42: Fredi Yulianto

Sheet Memo Setor
A1: 37 | C1: <<------ masukkan nomor yang akan dicetak advis nya
C2: MEMO SETORAN
C4: No Rekening | D4: : | E4: =VLOOKUP(A1,Original!A1:AL101,4) -> 0
C5: Nama | D5: : | E5: =VLOOKUP(A1,Original!A1:AL101,5) -> 0
C6: Nominal | D6: : | E6: Rp. | F6: 8500
C7: No Telpon | D7: :
C8: Berita (Bila Diperlakukan) | D8: :

Sheet Betabon
D4: KCP MMU Martapura
C6: Fredi Yulianto
C7: All Suspend Deposit (195.11.601)
C8: ="Penarikkan Tunai "&'OVB All Suspend'!C11 -> Penarikkan Tunai Tarik tunai Petty Cash + Tunj Pulsa
G12: 811000
B14: ='Rumus '!A172 -> #N/A
F16: Martapura, | G16: =NOW() -> 46314.614

Sheet Lebel
C2: REIMBURSE OPERASIONAL
C3: KCP MMU Martapura
C5: REIMBURSE LISTRIK KANTOR
C6: KCP MMU Martapura
C8: REIMBURSE PULSA BM
C9: KCP MMU Martapura
C11: REIMBURSE UTILITIS PLN BM
C12: KCP MMU Martapura
C14: PERJANJIAN SEWA MENYEWA
C15: KCP MMU Martapura
C17: REIMBURSE JASA KEBERSIHAN
C18: KCP MMU Martapura
... C24: KCP MMU Martapura

Sheet Rumus 
R5: Satuan | V5: =SUM(V7:V39) -> 0
Q6: 0 | S6: 0 | V6: =AY6 -> 0
Q7: 1 | R7: Satu | S7: Seratus | T7: Seribu | U7: & 1/100 | V7: =AY7 -> 0
Q8: 2 | R8: Dua | S8: Dua ratus | T8: Dua ribu | U8: & 2/100 | V8: =AY8 -> 0
Q9: 3 | R9: Tiga | S9: Tiga ratus | T9: Tiga ribu | U9: & 3/100 | V9: =AY9 -> 0
Q10: 4 | R10: Empat | S10: Empat ratus | T10: Empat ribu | U10: & 4/100 | V10: =AY10 -> 0
P11: " | Q11: 5 | R11: Lima | S11: Lima ratus | T11: Lima ribu | U11: & 5/100 | V11: =AY11 -> 0
P12: " | Q12: 6 | R12: Enam | S12: Enam ratus | T12: Enam ribu | U12: & 6/100 | V12: =AY12 -> 0
P13: " | Q13: 7 | R13: Tujuh | S13: Tujuh ratus | T13: Tujuh ribu | U13: & 7/100 | V13: =AY13 -> 0
P14: " | Q14: 8 | R14: Delapan | S14: Delapan ratus | T14: Delapan ribu | U14: & 8/100 | V14: =AY14 -> 0
P15: " | Q15: 9 | R15: Sembilan | S15: Sembilan ratus | T15: Sembilan ribu | U15: & 9/100 | V15: =AY15 -> 0
P16: " | Q16: 10 | R16: Sepuluh | T16: Sepuluh ribu | U16: & 10/100 | V16: =AY16 -> 0
F17: =TRUNC(+A19/1000000) -> 0 | P17: " | Q17: 11 | R17: Sebelas | T17: Sebelas ribu | U17: & 11/100 | V17: =AY17 -> 0
F18: =(+B22*100000+C22*1000+E22*100) -> #VALUE! | L18: ERR | P18: " | Q18: 12 | R18: Dua belas | T18: Dua belas ribu | U18: & 12/100 | V18: =AY18 -> 0
A19: =TRUNC(+A20) -> 23000 | E19: =TRUNC(+A19/100000000) -> 0 | P19: " | Q19: 13 | R19: Tiga belas | T19: Tiga belas ribu | U19: & 13/100 | V19: =AY19 -> 0
A20: =Advis!D25 -> 23000 | B20: Ratus | C20: Belas | E20: Belas | I20: =TRUNC((+A19-(+F17*1000000))/1000) -> 23 | K20: =(TRUNC((+A19-(+F17*1000000))/1))-I20*1000 -> 0 | P20: " | Q20: 14 | R20: Empat belas | T20: Empat belas ribu | U20: & 14/100 | V20: =AY20 -> 0
B21: Milyard | C21: Milyard | E21: Milyard | N21: =ROUND(((+A20-A19)*100),1) -> 0 | P21: " | Q21: 15 | R21: Lima belas | T21: Lima belas ribu | U21: & 15/100 | V21: =AY21 -> 0
B22: =TRUNC(+A20/100000000000) -> 0 | C22: =(TRUNC(+A19/1000000000))-B22*100 -> 0 | E22: =IF(E19>0,TRUNC(+E19-B22*1000-C22*10),"") | F22: =F17-F18 -> #VALUE! | G22: =G24 -> #VALUE! | H22: =TRUNC((+A19-(+F17*1000000))/100000) -> 0 | I22: =I20-H22*100 -> 23 | K22: =TRUNC(+K20/100) -> 0 | L22: =K20-K22*100 -> 0 | M22: =IF(N22>0," & Sen ","") | N22: =N21 -> 0 | P22: " | Q22: 16 | R22: Enam belas | T22: Enam belas ribu | U22: & 16/100 | V22: =AY22 -> 0
P23: " | Q23: 17 | R23: Tujuh belas | T23: Tujuh belas ribu | U23: & 17/100 | V23: =AY23 -> 0
A24: =B22*100000000000 -> 0 | B24: =IF(B22>0,VLOOKUP(B22,$Q$7:$T$15,3),"") | C24: =IF(C22>0,VLOOKUP(C22,Q7:R105,2),"") | D24: =IF(B19+C22>0," Milyar ","") | E24: =IF(E22>0,VLOOKUP(E22,$Q$7:$T$15,3),"") -> #N/A | F24: =IF(F22>0,VLOOKUP(F22,Q7:R105,2),"") -> #VALUE! | G24: =IF(F22+E22>0," Juta","") -> #VALUE! | H24: =IF(H22>0,VLOOKUP(H22,$Q$7:$T$15,3),"") | I24: =IF(I22=1," Se",IF(I22=0,"",VLOOKUP(I22,Q7:R105,2))) -> Dua puluh tiga | J24: =IF(I22+H22>0," ribu","") -> ribu | K24: =IF(K22>0,VLOOKUP(K22,Q7:S15,3),"") | L24: =IF(L22>0,VLOOKUP(L22,Q7:R105,2),"") | M24: =IF(N22>0,VLOOKUP(N21,Q6:U105,5)," Rupiah ") -> Rupiah | O24: =IF(N22>0," ====","") | P24: =IF(N22>0,"-","====") -> ==== | Q24: 18 | R24: Delapan belas | T24: Delapan belas ribu | U24: & 18/100 | V24: =AY24 -> 0
B25: =B24 | P25: " | Q25: 19 | R25: Sembilan belas | T25: Sembilan belas ribu | U25: & 19/100 | V25: =AY30 -> 0
B26: =C24 | P26: " | Q26: 20 | R26: Dua puluh | T26: Dua puluh ribu | U26: & 20/100 | V26: =AY31 -> 0
B27: =D24 | P27: " | Q27: 21 | R27: Dua puluh satu | T27: Dua puluh satu ribu | U27: & 21/100 | V27: =AY32 -> 0
B28: =E24 -> #N/A | Q28: 22 | R28: Dua puluh dua | T28: Dua puluh dua ribu | U28: & 22/100 | V28: =AY33 -> 0
B29: =F24 -> #VALUE! | P29: " | Q29: 23 | R29: Dua puluh tiga | T29: Dua puluh tiga ribu | U29: & 23/100 | V29: =AY34 -> 0
P30: " | Q30: 24 | R30: Dua puluh empat | T30: Dua puluh empat ribu | U30: & 24/100 | V30: =AY35 -> 0
P31: " | Q31: 25 | R31: Dua puluh lima | T31: Dua puluh lima ribu | U31: & 25/100 | V31: =AY36 -> 0
P32: " | Q32: 26 | R32: Dua puluh enam | T32: Dua puluh enam ribu | U32: & 26/100 | V32: =AY37 -> 0
Q33: 27 | R33: Dua puluh tujuh | T33: Dua puluh tujuh ribu | U33: & 27/100 | V33: =AY38 -> 0
Q34: 28 | R34: Dua puluh delapan | T34: Dua puluh delapan ribu | U34: & 28/100 | V34: =AY39 -> 0
Q35: 29 | R35: Dua puluh sembilan | T35: Dua puluh sembilan ribu | U35: & 29/100 | V35: =AY40 -> 0
Q36: 30 | R36: Tiga puluh | T36: Tiga puluh ribu | U36: & 30/100 | V36: =AY41 -> 0
Q37: 31 | R37: Tiga puluh satu | T37: Tiga puluh satu ribu | U37: & 31/100 | V37: =AY42 -> 0
Q38: 32 | R38: Tiga puluh dua | T38: Tiga puluh dua ribu | U38: & 32/100 | V38: =AY43 -> 0
B39: =G24 -> #VALUE! | Q39: 33 | R39: Tiga puluh tiga | T39: Tiga puluh tiga ribu | U39: & 33/100 | V39: =AY44 -> 0
B40: =H24 | Q40: 34 | R40: Tiga puluh empat | T40: Tiga puluh empat ribu | U40: & 34/100 | V40: =AY45 -> 0
B41: =I24 -> Dua puluh tiga | Q41: 35 | R41: Tiga puluh lima | T41: Tiga puluh lima ribu | U41: & 35/100 | V41: =AY46 -> 0
B42: =J24 -> ribu | Q42: 36 | R42: Tiga puluh enam | T42: Tiga puluh enam ribu | U42: & 36/100 | V42: =AY47 -> 0
B43: =K24 | Q43: 37 | R43: Tiga puluh tujuh | T43: Tiga puluh tujuh ribu | U43: & 37/100 | V43: =AY48 -> 0
B44: =L24 | Q44: 38 | R44: Tiga puluh delapan | T44: Tiga puluh delapan ribu | U44: & 38/100 | V44: =AY49 -> 0
...

Sheet Sheet1
R5: Satuan | V5: =SUM(V7:V39) -> 0
Q6: 0 | S6: 0 | V6: =AY6 -> 0
Q7: 1 | R7: Satu | S7: Seratus | T7: Seribu | U7: & 1/100 | V7: =AY7 -> 0
Q8: 2 | R8: Dua | S8: Dua ratus | T8: Dua ribu | U8: & 2/100 | V8: =AY8 -> 0
Q9: 3 | R9: Tiga | S9: Tiga ratus | T9: Tiga ribu | U9: & 3/100 | V9: =AY9 -> 0
Q10: 4 | R10: Empat | S10: Empat ratus | T10: Empat ribu | U10: & 4/100 | V10: =AY10 -> 0
P11: " | Q11: 5 | R11: Lima | S11: Lima ratus | T11: Lima ribu | U11: & 5/100 | V11: =AY11 -> 0
P12: " | Q12: 6 | R12: Enam | S12: Enam ratus | T12: Enam ribu | U12: & 6/100 | V12: =AY12 -> 0
P13: " | Q13: 7 | R13: Tujuh | S13: Tujuh ratus | T13: Tujuh ribu | U13: & 7/100 | V13: =AY13 -> 0
P14: " | Q14: 8 | R14: Delapan | S14: Delapan ratus | T14: Delapan ribu | U14: & 8/100 | V14: =AY14 -> 0
P15: " | Q15: 9 | R15: Sembilan | S15: Sembilan ratus | T15: Sembilan ribu | U15: & 9/100 | V15: =AY15 -> 0
P16: " | Q16: 10 | R16: Sepuluh | T16: Sepuluh ribu | U16: & 10/100 | V16: =AY16 -> 0
F17: =TRUNC(+A19/1000000) -> 0 | P17: " | Q17: 11 | R17: Sebelas | T17: Sebelas ribu | U17: & 11/100 | V17: =AY17 -> 0
F18: =(+B22*100000+C22*1000+E22*100) -> #VALUE! | L18: ERR | P18: " | Q18: 12 | R18: Dua belas | T18: Dua belas ribu | U18: & 12/100 | V18: =AY18 -> 0
A19: =TRUNC(+A20) -> 122 | E19: =TRUNC(+A19/100000000) -> 0 | P19: " | Q19: 13 | R19: Tiga belas | T19: Tiga belas ribu | U19: & 13/100 | V19: =AY19 -> 0
A20: 122 | B20: Ratus | C20: Belas | E20: Belas | I20: =TRUNC((+A19-(+F17*1000000))/1000) -> 0 | K20: =(TRUNC((+A19-(+F17*1000000))/1))-I20*1000 -> 122 | P20: " | Q20: 14 | R20: Empat belas | T20: Empat belas ribu | U20: & 14/100 | V20: =AY20 -> 0
B21: Milyard | C21: Milyard | E21: Milyard | N21: =ROUND(((+A20-A19)*100),1) -> 0 | P21: " | Q21: 15 | R21: Lima belas | T21: Lima belas ribu | U21: & 15/100 | V21: =AY21 -> 0
B22: =TRUNC(+A20/100000000000) -> 0 | C22: =(TRUNC(+A19/1000000000))-B22*100 -> 0 | E22: =IF(E19>0,TRUNC(+E19-B22*1000-C22*10),"") | F22: =F17-F18 -> #VALUE! | G22: =G24 -> #VALUE! | H22: =TRUNC((+A19-(+F17*1000000))/100000) -> 0 | I22: =I20-H22*100 -> 0 | K22: =TRUNC(+K20/100) -> 1 | L22: =K20-K22*100 -> 22 | M22: =IF(N22>0," & Sen ","") | N22: =N21 -> 0 | P22: " | Q22: 16 | R22: Enam belas | T22: Enam belas ribu | U22: & 16/100 | V22: =AY22 -> 0
P23: " | Q23: 17 | R23: Tujuh belas | T23: Tujuh belas ribu | U23: & 17/100 | V23: =AY23 -> 0
A24: =B22*100000000000 -> 0 | B24: =IF(B22>0,VLOOKUP(B22,$Q$7:$T$15,3),"") | C24: =IF(C22>0,VLOOKUP(C22,Q7:R105,2),"") | D24: =IF(B19+C22>0," Milyar ","") | E24: =IF(E22>0,VLOOKUP(E22,$Q$7:$T$15,3),"") -> #N/A | F24: =IF(F22>0,VLOOKUP(F22,Q7:R105,2),"") -> #VALUE! | G24: =IF(F22+E22>0," Juta","") -> #VALUE! | H24: =IF(H22>0,VLOOKUP(H22,$Q$7:$T$15,3),"") | I24: =IF(I22=1," Se",IF(I22=0,"",VLOOKUP(I22,Q7:R105,2))) | J24: =IF(I22+H22>0," ribu","") | K24: =IF(K22>0,VLOOKUP(K22,Q7:S15,3),"") -> Seratus | L24: =IF(L22>0,VLOOKUP(L22,Q7:R105,2),"") -> Dua puluh dua | M24: =IF(N22>0,VLOOKUP(N21,Q6:U105,5)," Rupiah ") -> Rupiah | O24: =IF(N22>0," ====","") | P24: =IF(N22>0,"-","====") -> ==== | Q24: 18 | R24: Delapan belas | T24: Delapan belas ribu | U24: & 18/100 | V24: =AY24 -> 0
B25: =B24 | P25: " | Q25: 19 | R25: Sembilan belas | T25: Sembilan belas ribu | U25: & 19/100 | V25: =AY30 -> 0
B26: =C24 | P26: " | Q26: 20 | R26: Dua puluh | T26: Dua puluh ribu | U26: & 20/100 | V26: =AY31 -> 0
B27: =D24 | P27: " | Q27: 21 | R27: Dua puluh satu | T27: Dua puluh satu ribu | U27: & 21/100 | V27: =AY32 -> 0
B28: =E24 -> #N/A | Q28: 22 | R28: Dua puluh dua | T28: Dua puluh dua ribu | U28: & 22/100 | V28: =AY33 -> 0
B29: =F24 -> #VALUE! | P29: " | Q29: 23 | R29: Dua puluh tiga | T29: Dua puluh tiga ribu | U29: & 23/100 | V29: =AY34 -> 0
P30: " | Q30: 24 | R30: Dua puluh empat | T30: Dua puluh empat ribu | U30: & 24/100 | V30: =AY35 -> 0
P31: " | Q31: 25 | R31: Dua puluh lima | T31: Dua puluh lima ribu | U31: & 25/100 | V31: =AY36 -> 0
P32: " | Q32: 26 | R32: Dua puluh enam | T32: Dua puluh enam ribu | U32: & 26/100 | V32: =AY37 -> 0
Q33: 27 | R33: Dua puluh tujuh | T33: Dua puluh tujuh ribu | U33: & 27/100 | V33: =AY38 -> 0
Q34: 28 | R34: Dua puluh delapan | T34: Dua puluh delapan ribu | U34: & 28/100 | V34: =AY39 -> 0
Q35: 29 | R35: Dua puluh sembilan | T35: Dua puluh sembilan ribu | U35: & 29/100 | V35: =AY40 -> 0
Q36: 30 | R36: Tiga puluh | T36: Tiga puluh ribu | U36: & 30/100 | V36: =AY41 -> 0
Q37: 31 | R37: Tiga puluh satu | T37: Tiga puluh satu ribu | U37: & 31/100 | V37: =AY42 -> 0
Q38: 32 | R38: Tiga puluh dua | T38: Tiga puluh dua ribu | U38: & 32/100 | V38: =AY43 -> 0
B39: =G24 -> #VALUE! | Q39: 33 | R39: Tiga puluh tiga | T39: Tiga puluh tiga ribu | U39: & 33/100 | V39: =AY44 -> 0
B40: =H24 | Q40: 34 | R40: Tiga puluh empat | T40: Tiga puluh empat ribu | U40: & 34/100 | V40: =AY45 -> 0
B41: =I24 | Q41: 35 | R41: Tiga puluh lima | T41: Tiga puluh lima ribu | U41: & 35/100 | V41: =AY46 -> 0
B42: =J24 | Q42: 36 | R42: Tiga puluh enam | T42: Tiga puluh enam ribu | U42: & 36/100 | V42: =AY47 -> 0
B43: =K24 -> Seratus | Q43: 37 | R43: Tiga puluh tujuh | T43: Tiga puluh tujuh ribu | U43: & 37/100 | V43: =AY48 -> 0
B44: =L24 -> Dua puluh dua | Q44: 38 | R44: Tiga puluh delapan | T44: Tiga puluh delapan ribu | U44: & 38/100 | V44: =AY49 -> 0
...

Sheet Sheet2
